<?xml version="1.0" ?>
<!-- =================================================================================== -->
<!-- |    This document was autogenerated by xacro from mh5.xacro                      | -->
<!-- |    EDITING THIS FILE BY HAND IS NOT RECOMMENDED                                 | -->
<!-- =================================================================================== -->
<robot name="yaskawa_mh5lf" xmlns:xacro="http://ros.org/wiki/xacro">
  
  <xacro:include filename="$(find yaskawa_mh5_description)/urdf/mh5_gazebo.urdf.xacro"/>
  <xacro:include filename="$(find yaskawa_mh5_description)/urdf/mh5_ros2_controller.urdf.xacro"/>

<!-- macro function for inertial-->

	<xacro:macro name="default_inertial" params="mass">
		<inertial>
			<mass value="${mass}"/>
			<inertia ixx="1.0" ixy="0.0" ixz="0.0"
					iyy="1.0" iyz="0.0"
					izz="1.0" />
		</inertial>
	</xacro:macro>

<!-- end of macro function for inertial -->
<!-- transmission for robot controller -->
  <xacro:macro name="default_transmission" params="number">
      <transmission name="transmission_${number}"> 
          <plugin>transmission_interface/SimpleTransmission</plugin>
          <actuator name="motor_${number}" role="actuator1">
              <joint name="joint_${number}" role="joint1">
                  <mechanical_reduction>1.0</mechanical_reduction>
              </joint>
          </actuator>
      </transmission>
  </xacro:macro>
<!-- end transmission for robot controller -->
  <!-- link list -->

  <link name = "world" />

  <link name="base_link">
    <xacro:default_inertial mass="1.0"/>
    <visual>
      <origin rpy="0 0 3.14159"/>
      <geometry>
        <mesh filename="package://yaskawa_mh5_description/meshes/mh5/visual/MH5_BASE_AXIS.stl"/>
      </geometry>
      <material name="blue">
        <color rgba="0 0 1 1"/>
      </material>
    </visual>
    <collision>
      <origin rpy="0 0 3.14159"/>
      <geometry>
        <mesh filename="package://yaskawa_mh5_description/meshes/mh5/collision/MH5_BASE_AXIS.stl"/>
      </geometry>
      <material name="yellow">
        <color rgba="0 1 1 1"/>
      </material>
    </collision>
  </link>


<!-- Camera Pole Link -->
<!-- <link name="camera_pole">
  <xacro:default_inertial mass="0.5"/>
  <visual>
    <origin xyz="1 0 0"/>
    <geometry>
      <cylinder length="1.0" radius="0.05"/>
    </geometry>
    <material name="grey">
      <color rgba="0.5 0.5 0.5 1.0"/>
    </material>
  </visual>
  <collision>
    <origin xyz="1 0 0"/>
    <geometry>
      <cylinder length="1.0" radius="0.05"/>
    </geometry>
  </collision>
</link> -->

<!-- Depth Camera Link -->
<!-- 
<link name="depth_camera">
  <xacro:default_inertial mass="0.5"/>
  <visual>
    <geometry>
      <box size="0.2 0.4 0.1"/>
    </geometry>
    <material name="black">
      <color rgba="0.0 0.0 0.0 1.0"/>
    </material>
  </visual>
  <collision>
    <geometry>
      <box size="0.2 0.4 0.1"/>
    </geometry>
  </collision>
</link> -->


<!-- Joint between camera pole and depth camera -->
<!-- <joint name="pole_to_camera" type="fixed">
  <parent link="camera_pole"/>
  <child link="depth_camera"/>
  <origin xyz="0 0 0.95" rpy="0 0 0"/>
  <axis xyz="0 1.5 0"/> 
</joint>  -->

  <link name="link_s">
    <xacro:default_inertial mass="1.0"/>
    <visual>
      <geometry>
        <mesh filename="package://yaskawa_mh5_description/meshes/mh5/visual/MH5_S_AXIS.stl"/>
      </geometry>
      <material name="silver">
        <color rgba="0.8 0.8 0.8 1"/>
      </material>
    </visual>
    <collision>
      <geometry>
        <mesh filename="package://yaskawa_mh5_description/meshes/mh5/collision/MH5_S_AXIS.stl"/>
      </geometry>
      <material name="yellow"/>
    </collision>
  </link>
  <link name="link_l">
    <xacro:default_inertial mass="1.0"/>
    <visual>
      <!-- <origin rpy="1.57 3.1416 0" xyz="0 0 0"/> -->
      <geometry>
        <mesh filename="package://yaskawa_mh5_description/meshes/mh5/visual/MH5_L_AXIS.stl"/>
      </geometry>
      <material name="blue"/>
    </visual>
    <collision>
      <!-- <origin rpy="1.57 3.1416 0" xyz="0 0 0"/> -->
      <geometry>
        <mesh filename="package://yaskawa_mh5_description/meshes/mh5/collision/MH5_L_AXIS.stl"/>
      </geometry>
      <material name="yellow"/>
      robot</collision>
  </link>
  <link name="link_u">
    <xacro:default_inertial mass="1.0"/>
    <visual>
      <!-- <origin rpy="1.57 -3.1415 0" xyz="0 0 0"/> -->
      <geometry>
        <mesh filename="package://yaskawa_mh5_description/meshes/mh5/visual/MH5_U_AXIS.stl"/>
      </geometry>
      <material name="blue"/>
    </visual>
    <collision>

      <geometry>
        <mesh filename="package://yaskawa_mh5_description/meshes/mh5/collision/MH5_U_AXIS.stl"/>
      </geometry>
      <material name="yellow"/>
    </collision>
  </link>
  <link name="link_r">
    <xacro:default_inertial mass="1.0"/>
    <visual>
      <geometry>
        <mesh filename="package://yaskawa_mh5_description/meshes/mh5/visual/MH5_R_AXIS.stl"/>
      </geometry>
      <material name="silver"/>
    </visual>
    <collision>
      <geometry>
        <mesh filename="package://yaskawa_mh5_description/meshes/mh5/collision/MH5_R_AXIS.stl"/>
      </geometry>
      <material name="yellow"/>
    </collision>
  </link>

<!-- 3D sensor  -->
  <link name="3d_camera">
    <xacro:default_inertial mass="0.5"/>
    <visual>
      <geometry>
          <mesh filename = "package://yaskawa_mh5_description/meshes/mh5/collision/BIN_PICKING_MODULE_1CH_ASM.stl" scale="0.001 0.001 0.001"/>
      </geometry>
      <material name="silver"/>
    </visual>
    <collision>
      <geometry>
        <mesh filename = "package://yaskawa_mh5_description/meshes/mh5/collision/BIN_PICKING_MODULE_1CH_ASM.stl" scale="0.001 0.001 0.001"/>
      </geometry>
      <material name="silver"/>
    </collision>
  </link>


  <link name="link_b">
    <xacro:default_inertial mass="1.0"/>
    <visual>

      <geometry>
        <mesh filename="package://yaskawa_mh5_description/meshes/mh5/visual/MH5_B_AXIS.stl"/>
      </geometry>
      <material name="blue"/>
    </visual>
    <collision>

      <geometry>
        <mesh filename="package://yaskawa_mh5_description/meshes/mh5/collision/MH5_B_AXIS.stl"/>
      </geometry>
      <material name="yellow"/>
    </collision>
  </link>
  <link name="link_t">
    <xacro:default_inertial mass="1.0"/>
    <visual>
      <geometry>
        <mesh filename="package://yaskawa_mh5_description/meshes/mh5/visual/MH5_T_AXIS.stl"/>
      </geometry>
      <material name="silver"/>
    </visual>
    <collision>
      <geometry>
        <mesh filename="package://yaskawa_mh5_description/meshes/mh5/collision/MH5_T_AXIS.stl"/>
      </geometry>
      <material name="yellow"/>
    </collision>
  </link>

  <joint name="virtual_joint" type="fixed">
    <origin xyz="0.0 0.0 0.0" rpy="0.0 0.0 0.0"/>
    <parent link="world"/>
    <child link="base_link"/>
    <axis xyz="0.0 0.0 0.0"/>
    <limit lower="0.0" upper="0.0" effort="0.0" velocity="0.0"/>
  </joint> 
  <!-- Joint between link_r and camera  -->
  <joint name="joint_3d_camera" type="fixed">
    <parent link="link_r"/>
    <child link="3d_camera"/>
    <origin xyz="0.0715 0 0.08" rpy="1.5708 0 1.5708"/>
  </joint>

  <joint name="joint_s" type="revolute">

    <parent link="base_link"/>
    <child link="link_s"/>
    <origin rpy="0 0 0" xyz="0 0 0.1990"/>
    <axis xyz="0 0 1"/>
    <limit effort="100" lower="-2.9671" upper="2.9671" velocity="2.96"/>
  </joint>
  <joint name="joint_l" type="revolute">
    <parent link="link_s"/>
    <child link="link_l"/>
    <origin rpy="0 0 0" xyz="0.0880 0 0.1310"/>
    <axis xyz="0 1 0"/>
    <limit effort="100" lower="-1.1345" upper="2.6180" velocity="2.96"/>
  </joint>
  <joint name="joint_u" type="revolute">
    <parent link="link_l"/>
    <child link="link_u"/>
    <origin rpy="0 0 0" xyz="0 0 0.3100"/>
    <axis xyz="0 -1 0"/>

    <limit effort="100" lower="-1.0122" upper="3.2218" velocity="2.96"/>
  </joint>
  <joint name="joint_r" type="revolute">
    <parent link="link_u"/>
    <child link="link_r"/>
    <origin rpy="0 0 0" xyz="0.0715 0 0.0399"/>
    <axis xyz="-1 0 0"/>
    <limit effort="100" lower="-3.3161" upper="3.3161" velocity="3.48"/>
  </joint>


  <joint name="joint_b" type="revolute">
    <parent link="link_r"/>
    <child link="link_b"/>
    <origin rpy="0 0 0" xyz="0.2335 0 0"/>
    <axis xyz="0 -1 0"/>
    <limit effort="100" lower="-2.1817" upper="2.1817" velocity="3.48"/>
  </joint>
  <joint name="joint_t" type="revolute">
    <parent link="link_b"/>"
    <child link="link_t"/>
    <origin rpy="0 0 0" xyz="0.0865 0 0"/>
    <axis xyz="-1 0 0"/>
    <limit effort="100" lower="-6.2831" upper="6.2831" velocity="6.97"/>
  </joint>


  <!-- Define transmissions -->
    <xacro:default_transmission number="s"/>
    <xacro:default_transmission number="l"/>
    <xacro:default_transmission number="u"/>
    <xacro:default_transmission number="r"/>
    <xacro:default_transmission number="b"/>
    <xacro:default_transmission number="t"/>    

</robot>