<sdf version='1.7'>
  <world name='default'>
    <light name='sun' type='directional'>
      <cast_shadows>1</cast_shadows>
      <pose>0 0 10 0 -0 0</pose>
      <diffuse>0.8 0.8 0.8 1</diffuse>
      <specular>0.2 0.2 0.2 1</specular>
      <attenuation>
        <range>1000</range>
        <constant>0.9</constant>
        <linear>0.01</linear>
        <quadratic>0.001</quadratic>
      </attenuation>
      <direction>-0.5 0.1 -0.9</direction>
      <spot>
        <inner_angle>0</inner_angle>
        <outer_angle>0</outer_angle>
        <falloff>0</falloff>
      </spot>
    </light>
    <model name='ground_plane'>
      <static>1</static>
      <link name='link'>
        <collision name='collision'>
          <geometry>
            <plane>
              <normal>0 0 1</normal>
              <size>100 100</size>
            </plane>
          </geometry>
          <surface>
            <friction>
              <ode>
                <mu>100</mu>
                <mu2>50</mu2>
              </ode>
              <torsional>
                <ode/>
              </torsional>
            </friction>
            <contact>
              <ode/>
            </contact>
            <bounce/>
          </surface>
          <max_contacts>10</max_contacts>
        </collision>
        <visual name='visual'>
          <cast_shadows>0</cast_shadows>
          <geometry>
            <plane>
              <normal>0 0 1</normal>
              <size>100 100</size>
            </plane>
          </geometry>
          <material>
            <script>
              <uri>file://media/materials/scripts/gazebo.material</uri>
              <name>Gazebo/Grey</name>
            </script>
          </material>
        </visual>
        <self_collide>0</self_collide>
        <enable_wind>0</enable_wind>
        <kinematic>0</kinematic>
      </link>
    </model>
    <gravity>0 0 -9.8</gravity>
    <magnetic_field>6e-06 2.3e-05 -4.2e-05</magnetic_field>
    <atmosphere type='adiabatic'/>
    <physics type='ode'>
      <max_step_size>0.001</max_step_size>
      <real_time_factor>1</real_time_factor>
      <real_time_update_rate>1000</real_time_update_rate>
    </physics>
    <scene>
      <ambient>0.4 0.4 0.4 1</ambient>
      <background>0.7 0.7 0.7 1</background>
      <shadows>1</shadows>
    </scene>
    <audio>
      <device>default</device>
    </audio>
    <wind/>
    <spherical_coordinates>
      <surface_model>EARTH_WGS84</surface_model>
      <latitude_deg>0</latitude_deg>
      <longitude_deg>0</longitude_deg>
      <elevation>0</elevation>
      <heading_deg>0</heading_deg>
    </spherical_coordinates>
    <model name='yaskawa_mh5lf'>
      <joint name='virtual_joint' type='fixed'>
        <pose relative_to='__model__'>0 0 0 0 -0 0</pose>
        <parent>world</parent>
        <child>base_link</child>
      </joint>
      <link name='base_link'>
        <pose relative_to='virtual_joint'>0 0 0 0 -0 0</pose>
        <inertial>
          <pose>0 0 0 0 -0 0</pose>
          <mass>1</mass>
          <inertia>
            <ixx>1</ixx>
            <ixy>0</ixy>
            <ixz>0</ixz>
            <iyy>1</iyy>
            <iyz>0</iyz>
            <izz>1</izz>
          </inertia>
        </inertial>
        <collision name='base_link_collision'>
          <pose>0 0 0 0 -0 3.14159</pose>
          <geometry>
            <mesh>
              <scale>1 1 1</scale>
              <uri>model://yaskawa_mh5_description/meshes/mh5/collision/MH5_BASE_AXIS.stl</uri>
            </mesh>
          </geometry>
          <max_contacts>10</max_contacts>
          <surface>
            <contact>
              <ode/>
            </contact>
            <bounce/>
            <friction>
              <torsional>
                <ode/>
              </torsional>
              <ode/>
            </friction>
          </surface>
        </collision>
        <visual name='base_link_visual'>
          <pose>0 0 0 0 -0 0</pose>
          <geometry>
            <mesh>
              <scale>1 1 1</scale>
              <uri>model://yaskawa_mh5_description/meshes/mh5/visual/MH5_BASE_AXIS.stl</uri>
            </mesh>
          </geometry>
        </visual>
        <self_collide>0</self_collide>
        <enable_wind>0</enable_wind>
        <kinematic>0</kinematic>
      </link>
      <joint name='joint_s' type='revolute'>
        <pose relative_to='base_link'>0 0 0.199 0 -0 0</pose>
        <parent>base_link</parent>
        <child>link_s</child>
        <axis>
          <xyz>0 0 1</xyz>
          <limit>
            <lower>-1.1345</lower>
            <upper>2.618</upper>
            <effort>100</effort>
            <velocity>2.96</velocity>
          </limit>
          <dynamics>
            <spring_reference>0</spring_reference>
            <spring_stiffness>0</spring_stiffness>
          </dynamics>
        </axis>
      </joint>
      <link name='link_s'>
        <pose relative_to='joint_s'>0 0 0 0 -0 0</pose>
        <inertial>
          <pose>0 0 0 0 -0 0</pose>
          <mass>1</mass>
          <inertia>
            <ixx>1</ixx>
            <ixy>0</ixy>
            <ixz>0</ixz>
            <iyy>1</iyy>
            <iyz>0</iyz>
            <izz>1</izz>
          </inertia>
        </inertial>
        <collision name='link_s_collision'>
          <pose>0 0 0 0 -0 0</pose>
          <geometry>
            <mesh>
              <scale>1 1 1</scale>
              <uri>model://yaskawa_mh5_description/meshes/mh5/collision/MH5_S_AXIS.stl</uri>
            </mesh>
          </geometry>
          <max_contacts>10</max_contacts>
          <surface>
            <contact>
              <ode/>
            </contact>
            <bounce/>
            <friction>
              <torsional>
                <ode/>
              </torsional>
              <ode/>
            </friction>
          </surface>
        </collision>
        <visual name='link_s_visual'>
          <pose>0 0 0 0 -0 0</pose>
          <geometry>
            <mesh>
              <scale>1 1 1</scale>
              <uri>model://yaskawa_mh5_description/meshes/mh5/visual/MH5_S_AXIS.stl</uri>
            </mesh>
          </geometry>
        </visual>
        <self_collide>0</self_collide>
        <enable_wind>0</enable_wind>
        <kinematic>0</kinematic>
      </link>
      <joint name='joint_l' type='revolute'>
        <pose relative_to='link_s'>0.088 0 0.131 0 -0 0</pose>
        <parent>link_s</parent>
        <child>link_l</child>
        <axis>
          <xyz>0 1 0</xyz>
          <limit>
            <lower>-1.1345</lower>
            <upper>2.618</upper>
            <effort>100</effort>
            <velocity>2.96</velocity>
          </limit>
          <dynamics>
            <spring_reference>0</spring_reference>
            <spring_stiffness>0</spring_stiffness>
          </dynamics>
        </axis>
      </joint>
      <link name='link_l'>
        <pose relative_to='joint_l'>0 0 0 0 -0 0</pose>
        <inertial>
          <pose>0 0 0 0 -0 0</pose>
          <mass>1</mass>
          <inertia>
            <ixx>1</ixx>
            <ixy>0</ixy>
            <ixz>0</ixz>
            <iyy>1</iyy>
            <iyz>0</iyz>
            <izz>1</izz>
          </inertia>
        </inertial>
        <collision name='link_l_collision'>
          <pose>0 0 0 0 -0 0</pose>
          <geometry>
            <mesh>
              <scale>1 1 1</scale>
              <uri>model://yaskawa_mh5_description/meshes/mh5/collision/MH5_L_AXIS.stl</uri>
            </mesh>
          </geometry>
          <max_contacts>10</max_contacts>
          <surface>
            <contact>
              <ode/>
            </contact>
            <bounce/>
            <friction>
              <torsional>
                <ode/>
              </torsional>
              <ode/>
            </friction>
          </surface>
        </collision>
        <visual name='link_l_visual'>
          <pose>0 0 0 0 -0 0</pose>
          <geometry>
            <mesh>
              <scale>1 1 1</scale>
              <uri>model://yaskawa_mh5_description/meshes/mh5/visual/MH5_L_AXIS.stl</uri>
            </mesh>
          </geometry>
        </visual>
        <self_collide>0</self_collide>
        <enable_wind>0</enable_wind>
        <kinematic>0</kinematic>
      </link>
      <joint name='joint_u' type='revolute'>
        <pose relative_to='link_l'>0 0 0.31 0 -0 0</pose>
        <parent>link_l</parent>
        <child>link_u</child>
        <axis>
          <xyz>0 -1 0</xyz>
          <limit>
            <lower>-1.0122</lower>
            <upper>3.2218</upper>
            <effort>100</effort>
            <velocity>2.96</velocity>
          </limit>
          <dynamics>
            <spring_reference>0</spring_reference>
            <spring_stiffness>0</spring_stiffness>
          </dynamics>
        </axis>
      </joint>
      <link name='link_u'>
        <pose relative_to='joint_u'>0 0 0 0 -0 0</pose>
        <inertial>
          <pose>0 0 0 0 -0 0</pose>
          <mass>1</mass>
          <inertia>
            <ixx>1</ixx>
            <ixy>0</ixy>
            <ixz>0</ixz>
            <iyy>1</iyy>
            <iyz>0</iyz>
            <izz>1</izz>
          </inertia>
        </inertial>
        <collision name='link_u_collision'>
          <pose>0 0 0 0 -0 0</pose>
          <geometry>
            <mesh>
              <scale>1 1 1</scale>
              <uri>model://yaskawa_mh5_description/meshes/mh5/collision/MH5_U_AXIS.stl</uri>
            </mesh>
          </geometry>
          <max_contacts>10</max_contacts>
          <surface>
            <contact>
              <ode/>
            </contact>
            <bounce/>
            <friction>
              <torsional>
                <ode/>
              </torsional>
              <ode/>
            </friction>
          </surface>
        </collision>
        <visual name='link_u_visual'>
          <pose>0 0 0 0 -0 0</pose>
          <geometry>
            <mesh>
              <scale>1 1 1</scale>
              <uri>model://yaskawa_mh5_description/meshes/mh5/visual/MH5_U_AXIS.stl</uri>
            </mesh>
          </geometry>
        </visual>
        <self_collide>0</self_collide>
        <enable_wind>0</enable_wind>
        <kinematic>0</kinematic>
      </link>
      <joint name='joint_r' type='revolute'>
        <pose relative_to='link_u'>0.0715 0 0.0399 0 -0 0</pose>
        <parent>link_u</parent>
        <child>link_r</child>
        <axis>
          <xyz>-1 0 0</xyz>
          <limit>
            <lower>-3.3161</lower>
            <upper>3.3161</upper>
            <effort>100</effort>
            <velocity>3.48</velocity>
          </limit>
          <dynamics>
            <spring_reference>0</spring_reference>
            <spring_stiffness>0</spring_stiffness>
          </dynamics>
        </axis>
      </joint>
      <link name='link_r'>
        <pose relative_to='joint_r'>0 0 0 0 -0 0</pose>
        <inertial>
          <pose>0.05075 0.019125 0.04 0 -0 0</pose>
          <mass>2</mass>
          <inertia>
            <ixx>3.00539</ixx>
            <ixy>-0.00308869</ixy>
            <ixz>-0.00405999</ixz>
            <iyy>3.00925</iyy>
            <iyz>-0.00153</iyz>
            <izz>3.00825</izz>
          </inertia>
        </inertial>
        <collision name='link_r_collision'>
          <pose>0 0 0 0 -0 0</pose>
          <geometry>
            <mesh>
              <scale>1 1 1</scale>
              <uri>model://yaskawa_mh5_description/meshes/mh5/collision/MH5_R_AXIS.stl</uri>
            </mesh>
          </geometry>
          <max_contacts>10</max_contacts>
          <surface>
            <contact>
              <ode/>
            </contact>
            <bounce/>
            <friction>
              <torsional>
                <ode/>
              </torsional>
              <ode/>
            </friction>
          </surface>
        </collision>
        <collision name='link_r_fixed_joint_lump__tesseravue_chassis_link_collision_1'>
          <pose>0.0715 0 0.08 1.5708 -0 1.5708</pose>
          <geometry>
            <mesh>
              <scale>0.001 0.001 0.001</scale>
              <uri>model://yaskawa_mh5_description/meshes/mh5/collision/BIN_PICKING_MODULE_1CH_ASM.stl</uri>
            </mesh>
          </geometry>
          <max_contacts>10</max_contacts>
          <surface>
            <contact>
              <ode/>
            </contact>
            <bounce/>
            <friction>
              <torsional>
                <ode/>
              </torsional>
              <ode/>
            </friction>
          </surface>
        </collision>
        <visual name='link_r_visual'>
          <pose>0 0 0 0 -0 0</pose>
          <geometry>
            <mesh>
              <scale>1 1 1</scale>
              <uri>model://yaskawa_mh5_description/meshes/mh5/visual/MH5_R_AXIS.stl</uri>
            </mesh>
          </geometry>
        </visual>
        <visual name='link_r_fixed_joint_lump__tesseravue_chassis_link_visual_1'>
          <pose>0.0715 0 0.08 1.5708 -0 1.5708</pose>
          <geometry>
            <mesh>
              <scale>0.001 0.001 0.001</scale>
              <uri>model://yaskawa_mh5_description/meshes/mh5/collision/BIN_PICKING_MODULE_1CH_ASM.stl</uri>
            </mesh>
          </geometry>
        </visual>
        <visual name='link_r_fixed_joint_lump__tesseravue_camera_link_visual_2'>
          <pose>0.1315 0.0765 0.08 1.5708 4e-06 0</pose>
          <geometry>
            <cylinder>
              <length>0.001</length>
              <radius>0.0005</radius>
            </cylinder>
          </geometry>
        </visual>
        <sensor name='TesseraVue' type='camera'>
          <visualize>1</visualize>
          <update_rate>12</update_rate>
          <camera name='TesseraVue'>
            <horizontal_fov>1.089</horizontal_fov>
            <image>
              <width>800</width>
              <height>800</height>
              <format>R8G8B8</format>
            </image>
            <clip>
              <near>0.05</near>
              <far>8</far>
            </clip>
          </camera>
          <plugin name='camera_controller' filename='libgazebo_ros_camera.so'>
            <frameName>3dcamera_optical</frameName>
            <min_depth>0.1</min_depth>
            <max_depth>100.0</max_depth>
          </plugin>
          <pose>0.1315 0.0765 0.08 1.5708 4e-06 0</pose>
        </sensor>
        <self_collide>0</self_collide>
        <enable_wind>0</enable_wind>
        <kinematic>0</kinematic>
      </link>
      <joint name='joint_b' type='revolute'>
        <pose relative_to='link_r'>0.2335 0 0 0 -0 0</pose>
        <parent>link_r</parent>
        <child>link_b</child>
        <axis>
          <xyz>0 -1 0</xyz>
          <limit>
            <lower>-2.1817</lower>
            <upper>2.1817</upper>
            <effort>100</effort>
            <velocity>3.48</velocity>
          </limit>
          <dynamics>
            <spring_reference>0</spring_reference>
            <spring_stiffness>0</spring_stiffness>
          </dynamics>
        </axis>
      </joint>
      <link name='link_b'>
        <pose relative_to='joint_b'>0 0 0 0 -0 0</pose>
        <inertial>
          <pose>0 0 0 0 -0 0</pose>
          <mass>1</mass>
          <inertia>
            <ixx>1</ixx>
            <ixy>0</ixy>
            <ixz>0</ixz>
            <iyy>1</iyy>
            <iyz>0</iyz>
            <izz>1</izz>
          </inertia>
        </inertial>
        <collision name='link_b_collision'>
          <pose>0 0 0 0 -0 0</pose>
          <geometry>
            <mesh>
              <scale>1 1 1</scale>
              <uri>model://yaskawa_mh5_description/meshes/mh5/collision/MH5_B_AXIS.stl</uri>
            </mesh>
          </geometry>
          <max_contacts>10</max_contacts>
          <surface>
            <contact>
              <ode/>
            </contact>
            <bounce/>
            <friction>
              <torsional>
                <ode/>
              </torsional>
              <ode/>
            </friction>
          </surface>
        </collision>
        <visual name='link_b_visual'>
          <pose>0 0 0 0 -0 0</pose>
          <geometry>
            <mesh>
              <scale>1 1 1</scale>
              <uri>model://yaskawa_mh5_description/meshes/mh5/visual/MH5_B_AXIS.stl</uri>
            </mesh>
          </geometry>
        </visual>
        <self_collide>0</self_collide>
        <enable_wind>0</enable_wind>
        <kinematic>0</kinematic>
      </link>
      <joint name='joint_t' type='revolute'>
        <pose relative_to='link_b'>0.0865 0 0 0 -0 0</pose>
        <parent>link_b</parent>
        <child>link_t</child>
        <axis>
          <xyz>-1 0 0</xyz>
          <limit>
            <lower>-6.2831</lower>
            <upper>6.2831</upper>
            <effort>100</effort>
            <velocity>6.97</velocity>
          </limit>
          <dynamics>
            <spring_reference>0</spring_reference>
            <spring_stiffness>0</spring_stiffness>
          </dynamics>
        </axis>
      </joint>
      <link name='link_t'>
        <pose relative_to='joint_t'>0 0 0 0 -0 0</pose>
        <inertial>
          <pose>0 0 0 0 -0 0</pose>
          <mass>1</mass>
          <inertia>
            <ixx>1</ixx>
            <ixy>0</ixy>
            <ixz>0</ixz>
            <iyy>1</iyy>
            <iyz>0</iyz>
            <izz>1</izz>
          </inertia>
        </inertial>
        <collision name='link_t_collision'>
          <pose>0 0 0 0 -0 0</pose>
          <geometry>
            <mesh>
              <scale>1 1 1</scale>
              <uri>model://yaskawa_mh5_description/meshes/mh5/collision/MH5_T_AXIS.stl</uri>
            </mesh>
          </geometry>
          <max_contacts>10</max_contacts>
          <surface>
            <contact>
              <ode/>
            </contact>
            <bounce/>
            <friction>
              <torsional>
                <ode/>
              </torsional>
              <ode/>
            </friction>
          </surface>
        </collision>
        <visual name='link_t_visual'>
          <pose>0 0 0 0 -0 0</pose>
          <geometry>
            <mesh>
              <scale>1 1 1</scale>
              <uri>model://yaskawa_mh5_description/meshes/mh5/visual/MH5_T_AXIS.stl</uri>
            </mesh>
          </geometry>
        </visual>
        <self_collide>0</self_collide>
        <enable_wind>0</enable_wind>
        <kinematic>0</kinematic>
      </link>
      <static>0</static>
      <plugin name='gazebo_ros2_control' filename='libgazebo_ros2_control.so'>
        <robot_param>robot_description</robot_param>
        <robot_param_node>robot_state_publisher</robot_param_node>
        <parameters>/home/ubuntu/ros2-dev/3D-sensor-robot-arm-simulation/install/yaskawa_mh5_controller/share/yaskawa_mh5_controller/config/mh5_ros2_controller.yaml</parameters>
      </plugin>
      <pose>0 0 0 0 -0 0</pose>
    </model>
    <model name='beer'>
      <link name='link'>
        <pose>0 0 0.115 0 -0 0</pose>
        <inertial>
          <mass>0.39</mass>
          <inertia>
            <ixx>0.00058</ixx>
            <ixy>0</ixy>
            <ixz>0</ixz>
            <iyy>0.00058</iyy>
            <iyz>0</iyz>
            <izz>0.00019</izz>
          </inertia>
          <pose>0 0 0 0 -0 0</pose>
        </inertial>
        <collision name='collision'>
          <geometry>
            <cylinder>
              <radius>0.055</radius>
              <length>0.23</length>
            </cylinder>
          </geometry>
          <max_contacts>10</max_contacts>
          <surface>
            <contact>
              <ode/>
            </contact>
            <bounce/>
            <friction>
              <torsional>
                <ode/>
              </torsional>
              <ode/>
            </friction>
          </surface>
        </collision>
        <visual name='visual'>
          <geometry>
            <cylinder>
              <radius>0.055</radius>
              <length>0.23</length>
            </cylinder>
          </geometry>
          <material>
            <script>
              <uri>model://beer/materials/scripts</uri>
              <uri>model://beer/materials/textures</uri>
              <name>Beer/Diffuse</name>
            </script>
          </material>
        </visual>
        <self_collide>0</self_collide>
        <enable_wind>0</enable_wind>
        <kinematic>0</kinematic>
      </link>
      <pose>0.844715 0.155051 0 0 -0 0</pose>
    </model>
    <model name='bowl'>
      <link name='link'>
        <inertial>
          <pose>0 0 0.0175 0 -0 0</pose>
          <mass>0.1</mass>
          <inertia>
            <ixx>0.000250308</ixx>
            <ixy>0</ixy>
            <ixz>0</ixz>
            <iyy>0.000250308</iyy>
            <iyz>0</iyz>
            <izz>0.0004802</izz>
          </inertia>
        </inertial>
        <collision name='collision'>
          <pose>0 0 0.0175 0 -0 0</pose>
          <geometry>
            <cylinder>
              <radius>0.098</radius>
              <length>0.035</length>
            </cylinder>
          </geometry>
          <max_contacts>10</max_contacts>
          <surface>
            <contact>
              <ode/>
            </contact>
            <bounce/>
            <friction>
              <torsional>
                <ode/>
              </torsional>
              <ode/>
            </friction>
          </surface>
        </collision>
        <visual name='visual'>
          <geometry>
            <mesh>
              <uri>model://bowl/meshes/bowl.dae</uri>
            </mesh>
          </geometry>
        </visual>
        <self_collide>0</self_collide>
        <enable_wind>0</enable_wind>
        <kinematic>0</kinematic>
      </link>
      <pose>0.56985 0.060702 0 0 -0 0</pose>
    </model>
    <model name='coke_can'>
      <link name='link'>
        <inertial>
          <pose>0 0 0.06 0 -0 0</pose>
          <mass>0.39</mass>
          <inertia>
            <ixx>0.00055575</ixx>
            <ixy>0</ixy>
            <ixz>0</ixz>
            <iyy>0.00055575</iyy>
            <iyz>0</iyz>
            <izz>0.0001755</izz>
          </inertia>
        </inertial>
        <collision name='collision'>
          <pose>0.003937 0.004724 -0.18 0 -0 0</pose>
          <geometry>
            <mesh>
              <uri>model://coke_can/meshes/coke_can.dae</uri>
            </mesh>
          </geometry>
          <surface>
            <friction>
              <ode>
                <mu>1</mu>
                <mu2>1</mu2>
              </ode>
              <torsional>
                <ode/>
              </torsional>
            </friction>
            <contact>
              <ode>
                <kp>1e+07</kp>
                <kd>1</kd>
                <min_depth>0.001</min_depth>
                <max_vel>0.1</max_vel>
              </ode>
            </contact>
            <bounce/>
          </surface>
          <max_contacts>10</max_contacts>
        </collision>
        <visual name='visual'>
          <pose>0.003937 0.004724 -0.18 0 -0 0</pose>
          <geometry>
            <mesh>
              <uri>model://coke_can/meshes/coke_can.dae</uri>
            </mesh>
          </geometry>
        </visual>
        <self_collide>0</self_collide>
        <enable_wind>0</enable_wind>
        <kinematic>0</kinematic>
      </link>
      <pose>0.627424 -0.646476 0 0 -0 0</pose>
    </model>
    <model name='coke_can_0'>
      <link name='link'>
        <inertial>
          <pose>0 0 0.06 0 -0 0</pose>
          <mass>0.39</mass>
          <inertia>
            <ixx>0.00055575</ixx>
            <ixy>0</ixy>
            <ixz>0</ixz>
            <iyy>0.00055575</iyy>
            <iyz>0</iyz>
            <izz>0.0001755</izz>
          </inertia>
        </inertial>
        <collision name='collision'>
          <pose>0.003937 0.004724 -0.18 0 -0 0</pose>
          <geometry>
            <mesh>
              <uri>model://coke_can/meshes/coke_can.dae</uri>
            </mesh>
          </geometry>
          <surface>
            <friction>
              <ode>
                <mu>1</mu>
                <mu2>1</mu2>
              </ode>
              <torsional>
                <ode/>
              </torsional>
            </friction>
            <contact>
              <ode>
                <kp>1e+07</kp>
                <kd>1</kd>
                <min_depth>0.001</min_depth>
                <max_vel>0.1</max_vel>
              </ode>
            </contact>
            <bounce/>
          </surface>
          <max_contacts>10</max_contacts>
        </collision>
        <visual name='visual'>
          <pose>0.003937 0.004724 -0.18 0 -0 0</pose>
          <geometry>
            <mesh>
              <uri>model://coke_can/meshes/coke_can.dae</uri>
            </mesh>
          </geometry>
        </visual>
        <self_collide>0</self_collide>
        <enable_wind>0</enable_wind>
        <kinematic>0</kinematic>
      </link>
      <pose>0.574492 0.073599 0 0 -0 0</pose>
    </model>
    <state world_name='default'>
      <sim_time>93 390000000</sim_time>
      <real_time>94 434371417</real_time>
      <wall_time>1720383292 572220885</wall_time>
      <iterations>93390</iterations>
      <model name='beer'>
        <pose>0.844715 0.155051 -7e-06 -1e-06 -0 -4e-06</pose>
        <scale>1 1 1</scale>
        <link name='link'>
          <pose>0.844715 0.155051 0.114993 -1e-06 -0 -4e-06</pose>
          <velocity>0 0 0 0 -0 0</velocity>
          <acceleration>0 0 -9.8 0 -0 0</acceleration>
          <wrench>0 0 -3.822 0 -0 0</wrench>
        </link>
      </model>
      <model name='bowl'>
        <pose>0.569984 0.060872 0.00078 0.006127 0.005085 -0.001061</pose>
        <scale>1 1 1</scale>
        <link name='link'>
          <pose>0.569984 0.060872 0.00078 0.006127 0.005085 -0.001061</pose>
          <velocity>0 0 0 0 -0 0</velocity>
          <acceleration>0.015133 0.035978 -0.07897 -1.73992 0.787746 -0.030061</acceleration>
          <wrench>0.001513 0.003598 -0.007897 0 -0 0</wrench>
        </link>
      </model>
      <model name='coke_can'>
        <pose>0.627407 -0.646618 -0.002689 -0.056829 0.006551 -0.000501</pose>
        <scale>1 1 1</scale>
        <link name='link'>
          <pose>0.627407 -0.646618 -0.002689 -0.056829 0.006551 -0.000501</pose>
          <velocity>0 0 0 0 -0 0</velocity>
          <acceleration>-0.018644 -0.040396 -0.000436 0.703947 -0.32658 -0.025516</acceleration>
          <wrench>-0.007271 -0.015755 -0.00017 0 -0 0</wrench>
        </link>
      </model>
      <model name='coke_can_0'>
        <pose>0.574806 0.073553 -0.002447 -0.01472 -0.028093 -0.003468</pose>
        <scale>1 1 1</scale>
        <link name='link'>
          <pose>0.574806 0.073553 -0.002447 -0.01472 -0.028093 -0.003468</pose>
          <velocity>0 0 0 0 -0 0</velocity>
          <acceleration>0.299906 0.486396 0.034885 -2.26581 -1.01159 -2.09767</acceleration>
          <wrench>0.116963 0.189695 0.013605 0 -0 0</wrench>
        </link>
      </model>
      <model name='ground_plane'>
        <pose>0 0 0 0 -0 0</pose>
        <scale>1 1 1</scale>
        <link name='link'>
          <pose>0 0 0 0 -0 0</pose>
          <velocity>0 0 0 0 -0 0</velocity>
          <acceleration>0 0 0 0 -0 0</acceleration>
          <wrench>0 0 0 0 -0 0</wrench>
        </link>
      </model>
      <model name='yaskawa_mh5lf'>
        <pose>-0 -0 2e-05 2e-06 -1e-06 -0</pose>
        <scale>1 1 1</scale>
        <link name='base_link'>
          <pose>-0 -0 2e-05 2e-06 -1e-06 -0</pose>
          <velocity>0 0 -0.004883 -0.000443 0.000239 0</velocity>
          <acceleration>1e-05 0.000153 -9.766 -0.88651 0.477154 -0.000181</acceleration>
          <wrench>1e-05 0.000153 -9.766 0 -0 0</wrench>
        </link>
        <link name='link_b'>
          <pose>0.391715 -0.000216 0.622468 -0.008264 0.036766 0.000712</pose>
          <velocity>-4.7e-05 0.000247 -0.004532 0.000418 -0.000225 -0.000154</velocity>
          <acceleration>0.101092 0.523234 -9.50884 -0.025481 0.013406 -0.153705</acceleration>
          <wrench>0.101092 0.523234 -9.50884 0 -0 0</wrench>
        </link>
        <link name='link_l'>
          <pose>0.088 -4.9e-05 0.330019 2e-06 -0.010915 -0.000549</pose>
          <velocity>7.7e-05 0.000135 -0.00476 -0.000432 -0.000404 5e-06</velocity>
          <acceleration>0.155441 0.281816 -9.66447 -0.875404 -0.165905 0.004614</acceleration>
          <wrench>0.155441 0.281816 -9.66447 0 -0 0</wrench>
        </link>
        <link name='link_r'>
          <pose>0.16229 -9e-05 0.665903 -0.008405 0.187107 -0.000548</pose>
          <velocity>-5.5e-05 0.000267 -0.004601 0.000418 -0.000175 -0.000154</velocity>
          <acceleration>0.109265 0.554196 -9.52693 -0.024943 0.063943 -0.154314</acceleration>
          <wrench>0.218529 1.10839 -19.0539 0 -0 0</wrench>
        </link>
        <link name='link_s'>
          <pose>-0 -0 0.199019 2e-06 -1e-06 -0.000549</pose>
          <velocity>4.7e-05 8.4e-05 -0.004813 -0.000437 0.000232 5e-06</velocity>
          <acceleration>0.094492 0.172268 -9.69559 -0.880074 0.470874 0.004968</acceleration>
          <wrench>0.094492 0.172268 -9.69559 0 -0 0</wrench>
        </link>
        <link name='link_t'>
          <pose>0.478156 -0.000154 0.619288 1.8e-05 0.036766 0.000712</pose>
          <velocity>-4.7e-05 0.000232 -0.004476 0.000438 -0.000226 -0.000154</velocity>
          <acceleration>0.100436 0.506685 -9.47348 -0.005667 0.012929 -0.153821</acceleration>
          <wrench>0.100436 0.506685 -9.47348 0 -0 0</wrench>
        </link>
        <link name='link_u'>
          <pose>0.084616 -4.7e-05 0.64 2e-06 0.187107 -0.000548</pose>
          <velocity>-4.9e-05 0.000262 -0.004691 -0.000427 -0.000174 5e-06</velocity>
          <acceleration>0.103228 0.546195 -9.59459 -0.87043 0.064979 0.0051</acceleration>
          <wrench>0.103228 0.546195 -9.59459 0 -0 0</wrench>
        </link>
      </model>
      <light name='sun'>
        <pose>0 0 10 0 -0 0</pose>
      </light>
    </state>
    <gui fullscreen='0'>
      <camera name='user_camera'>
        <pose>0.076321 -4.30668 0.930507 0 0.107643 1.4082</pose>
        <view_controller>orbit</view_controller>
        <projection_type>perspective</projection_type>
      </camera>
    </gui>
  </world>
</sdf>
