<sdf version='1.7'>
  <world name='default'>
    <light name='sun' type='directional'>
      <cast_shadows>1</cast_shadows>
      <pose>0 0 10 0 -0 0</pose>
      <diffuse>0.8 0.8 0.8 1</diffuse>
      <specular>0.2 0.2 0.2 1</specular>
      <attenuation>
        <range>1000</range>
        <constant>0.9</constant>
        <linear>0.01</linear>
        <quadratic>0.001</quadratic>
      </attenuation>
      <direction>-0.5 0.1 -0.9</direction>
      <spot>
        <inner_angle>0</inner_angle>
        <outer_angle>0</outer_angle>
        <falloff>0</falloff>
      </spot>
    </light>
    <model name='ground_plane'>
      <static>1</static>
      <link name='link'>
        <collision name='collision'>
          <geometry>
            <plane>
              <normal>0 0 1</normal>
              <size>100 100</size>
            </plane>
          </geometry>
          <surface>
            <friction>
              <ode>
                <mu>100</mu>
                <mu2>50</mu2>
              </ode>
              <torsional>
                <ode/>
              </torsional>
            </friction>
            <contact>
              <ode/>
            </contact>
            <bounce/>
          </surface>
          <max_contacts>10</max_contacts>
        </collision>
        <visual name='visual'>
          <cast_shadows>0</cast_shadows>
          <geometry>
            <plane>
              <normal>0 0 1</normal>
              <size>100 100</size>
            </plane>
          </geometry>
          <material>
            <script>
              <uri>file://media/materials/scripts/gazebo.material</uri>
              <name>Gazebo/Grey</name>
            </script>
          </material>
        </visual>
        <self_collide>0</self_collide>
        <enable_wind>0</enable_wind>
        <kinematic>0</kinematic>
      </link>
    </model>
    <gravity>0 0 -9.8</gravity>
    <magnetic_field>6e-06 2.3e-05 -4.2e-05</magnetic_field>
    <atmosphere type='adiabatic'/>
    <physics type='ode'>
      <max_step_size>0.001</max_step_size>
      <real_time_factor>1</real_time_factor>
      <real_time_update_rate>1000</real_time_update_rate>
    </physics>
    <scene>
      <ambient>0.4 0.4 0.4 1</ambient>
      <background>0.7 0.7 0.7 1</background>
      <shadows>1</shadows>
    </scene>
    <audio>
      <device>default</device>
    </audio>
    <wind/>
    <spherical_coordinates>
      <surface_model>EARTH_WGS84</surface_model>
      <latitude_deg>0</latitude_deg>
      <longitude_deg>0</longitude_deg>
      <elevation>0</elevation>
      <heading_deg>0</heading_deg>
    </spherical_coordinates>
    <model name='yaskawa_mh5lf'>
      <joint name='virtual_joint' type='fixed'>
        <pose relative_to='__model__'>0 0 0 0 -0 0</pose>
        <parent>world</parent>
        <child>base_link</child>
      </joint>
      <link name='base_link'>
        <pose relative_to='virtual_joint'>0 0 0 0 -0 0</pose>
        <inertial>
          <pose>0 0 0 0 -0 0</pose>
          <mass>1</mass>
          <inertia>
            <ixx>1</ixx>
            <ixy>0</ixy>
            <ixz>0</ixz>
            <iyy>1</iyy>
            <iyz>0</iyz>
            <izz>1</izz>
          </inertia>
        </inertial>
        <collision name='base_link_collision'>
          <pose>0 0 0 0 -0 3.14159</pose>
          <geometry>
            <mesh>
              <scale>2 2 2</scale>
              <uri>model://yaskawa_mh5_description/meshes/mh5/collision/MH5_BASE_AXIS.stl</uri>
            </mesh>
          </geometry>
          <max_contacts>10</max_contacts>
          <surface>
            <contact>
              <ode/>
            </contact>
            <bounce/>
            <friction>
              <torsional>
                <ode/>
              </torsional>
              <ode/>
            </friction>
          </surface>
        </collision>
        <visual name='base_link_visual'>
          <pose>0 0 0 0 -0 3.14159</pose>
          <geometry>
            <mesh>
              <scale>2 2 2</scale>
              <uri>model://yaskawa_mh5_description/meshes/mh5/visual/MH5_BASE_AXIS.stl</uri>
            </mesh>
          </geometry>
        </visual>
        <self_collide>0</self_collide>
        <enable_wind>0</enable_wind>
        <kinematic>0</kinematic>
      </link>
      <joint name='joint_s' type='revolute'>
        <pose relative_to='base_link'>0 0 0.199 0 -0 0</pose>
        <parent>base_link</parent>
        <child>link_s</child>
        <axis>
          <xyz>0 0 1</xyz>
          <limit>
            <lower>-2.9671</lower>
            <upper>2.9671</upper>
            <effort>100</effort>
            <velocity>2.96</velocity>
          </limit>
          <dynamics>
            <spring_reference>0</spring_reference>
            <spring_stiffness>0</spring_stiffness>
          </dynamics>
        </axis>
      </joint>
      <link name='link_s'>
        <pose relative_to='joint_s'>0 0 0 0 -0 0</pose>
        <inertial>
          <pose>0 0 0 0 -0 0</pose>
          <mass>1</mass>
          <inertia>
            <ixx>1</ixx>
            <ixy>0</ixy>
            <ixz>0</ixz>
            <iyy>1</iyy>
            <iyz>0</iyz>
            <izz>1</izz>
          </inertia>
        </inertial>
        <collision name='link_s_collision'>
          <pose>0 0 0 0 -0 0</pose>
          <geometry>
            <mesh>
              <scale>2 2 2</scale>
              <uri>model://yaskawa_mh5_description/meshes/mh5/collision/MH5_S_AXIS.stl</uri>
            </mesh>
          </geometry>
          <max_contacts>10</max_contacts>
          <surface>
            <contact>
              <ode/>
            </contact>
            <bounce/>
            <friction>
              <torsional>
                <ode/>
              </torsional>
              <ode/>
            </friction>
          </surface>
        </collision>
        <visual name='link_s_visual'>
          <pose>0 0 0 0 -0 0</pose>
          <geometry>
            <mesh>
              <scale>2 2 2</scale>
              <uri>model://yaskawa_mh5_description/meshes/mh5/visual/MH5_S_AXIS.stl</uri>
            </mesh>
          </geometry>
        </visual>
        <self_collide>0</self_collide>
        <enable_wind>0</enable_wind>
        <kinematic>0</kinematic>
      </link>
      <joint name='joint_l' type='revolute'>
        <pose relative_to='link_s'>0.176 0 0.262 0 -0 0</pose>
        <parent>link_s</parent>
        <child>link_l</child>
        <axis>
          <xyz>0 1 0</xyz>
          <limit>
            <lower>-1.1345</lower>
            <upper>2.618</upper>
            <effort>100</effort>
            <velocity>2.96</velocity>
          </limit>
          <dynamics>
            <spring_reference>0</spring_reference>
            <spring_stiffness>0</spring_stiffness>
          </dynamics>
        </axis>
      </joint>
      <link name='link_l'>
        <pose relative_to='joint_l'>0 0 0 0 -0 0</pose>
        <inertial>
          <pose>0 0 0 0 -0 0</pose>
          <mass>1</mass>
          <inertia>
            <ixx>1</ixx>
            <ixy>0</ixy>
            <ixz>0</ixz>
            <iyy>1</iyy>
            <iyz>0</iyz>
            <izz>1</izz>
          </inertia>
        </inertial>
        <collision name='link_l_collision'>
          <pose>0 0 0 0 -0 0</pose>
          <geometry>
            <mesh>
              <scale>2 2 2</scale>
              <uri>model://yaskawa_mh5_description/meshes/mh5/collision/MH5_L_AXIS.stl</uri>
            </mesh>
          </geometry>
          <max_contacts>10</max_contacts>
          <surface>
            <contact>
              <ode/>
            </contact>
            <bounce/>
            <friction>
              <torsional>
                <ode/>
              </torsional>
              <ode/>
            </friction>
          </surface>
        </collision>
        <visual name='link_l_visual'>
          <pose>0 0 0 0 -0 0</pose>
          <geometry>
            <mesh>
              <scale>2 2 2</scale>
              <uri>model://yaskawa_mh5_description/meshes/mh5/visual/MH5_L_AXIS.stl</uri>
            </mesh>
          </geometry>
        </visual>
        <self_collide>0</self_collide>
        <enable_wind>0</enable_wind>
        <kinematic>0</kinematic>
      </link>
      <joint name='joint_u' type='revolute'>
        <pose relative_to='link_l'>0 0 0.62 0 -0 0</pose>
        <parent>link_l</parent>
        <child>link_u</child>
        <axis>
          <xyz>0 -1 0</xyz>
          <limit>
            <lower>-1.0122</lower>
            <upper>3.2218</upper>
            <effort>100</effort>
            <velocity>2.96</velocity>
          </limit>
          <dynamics>
            <spring_reference>0</spring_reference>
            <spring_stiffness>0</spring_stiffness>
          </dynamics>
        </axis>
      </joint>
      <link name='link_u'>
        <pose relative_to='joint_u'>0 0 0 0 -0 0</pose>
        <inertial>
          <pose>0 0 0 0 -0 0</pose>
          <mass>1</mass>
          <inertia>
            <ixx>1</ixx>
            <ixy>0</ixy>
            <ixz>0</ixz>
            <iyy>1</iyy>
            <iyz>0</iyz>
            <izz>1</izz>
          </inertia>
        </inertial>
        <collision name='link_u_collision'>
          <pose>0 0 0 0 -0 0</pose>
          <geometry>
            <mesh>
              <scale>2 2 2</scale>
              <uri>model://yaskawa_mh5_description/meshes/mh5/collision/MH5_U_AXIS.stl</uri>
            </mesh>
          </geometry>
          <max_contacts>10</max_contacts>
          <surface>
            <contact>
              <ode/>
            </contact>
            <bounce/>
            <friction>
              <torsional>
                <ode/>
              </torsional>
              <ode/>
            </friction>
          </surface>
        </collision>
        <visual name='link_u_visual'>
          <pose>0 0 0 0 -0 0</pose>
          <geometry>
            <mesh>
              <scale>2 2 2</scale>
              <uri>model://yaskawa_mh5_description/meshes/mh5/visual/MH5_U_AXIS.stl</uri>
            </mesh>
          </geometry>
        </visual>
        <self_collide>0</self_collide>
        <enable_wind>0</enable_wind>
        <kinematic>0</kinematic>
      </link>
      <joint name='joint_r' type='revolute'>
        <pose relative_to='link_u'>0.143 0 0.0798 0 -0 0</pose>
        <parent>link_u</parent>
        <child>link_r</child>
        <axis>
          <xyz>-1 0 0</xyz>
          <limit>
            <lower>-3.3161</lower>
            <upper>3.3161</upper>
            <effort>100</effort>
            <velocity>3.48</velocity>
          </limit>
          <dynamics>
            <spring_reference>0</spring_reference>
            <spring_stiffness>0</spring_stiffness>
          </dynamics>
        </axis>
      </joint>
      <link name='link_r'>
        <pose relative_to='joint_r'>0 0 0 0 -0 0</pose>
        <inertial>
          <pose>0.13075 0.049 0.0575 0 -0 0</pose>
          <mass>2</mass>
          <inertia>
            <ixx>3.01494</ixx>
            <ixy>-0.0219337</ixy>
            <ixz>-0.021686</ixz>
            <iyy>3.07813</iyy>
            <iyz>-0.007315</iyz>
            <izz>3.0774</izz>
          </inertia>
        </inertial>
        <collision name='link_r_collision'>
          <pose>0 0 0 0 -0 0</pose>
          <geometry>
            <mesh>
              <scale>2 2 2</scale>
              <uri>model://yaskawa_mh5_description/meshes/mh5/collision/MH5_R_AXIS.stl</uri>
            </mesh>
          </geometry>
          <max_contacts>10</max_contacts>
          <surface>
            <contact>
              <ode/>
            </contact>
            <bounce/>
            <friction>
              <torsional>
                <ode/>
              </torsional>
              <ode/>
            </friction>
          </surface>
        </collision>
        <collision name='link_r_fixed_joint_lump__tesseravue_chassis_link_collision_1'>
          <pose>0.0715 0.05 0.08 1.5708 -0 1.5708</pose>
          <geometry>
            <mesh>
              <scale>0.0015 0.0015 0.0015</scale>
              <uri>model://yaskawa_mh5_description/meshes/mh5/collision/BIN_PICKING_MODULE_1CH_ASM.stl</uri>
            </mesh>
          </geometry>
          <max_contacts>10</max_contacts>
          <surface>
            <contact>
              <ode/>
            </contact>
            <bounce/>
            <friction>
              <torsional>
                <ode/>
              </torsional>
              <ode/>
            </friction>
          </surface>
        </collision>
        <visual name='link_r_visual'>
          <pose>0 0 0 0 -0 0</pose>
          <geometry>
            <mesh>
              <scale>2 2 2</scale>
              <uri>model://yaskawa_mh5_description/meshes/mh5/visual/MH5_R_AXIS.stl</uri>
            </mesh>
          </geometry>
        </visual>
        <visual name='link_r_fixed_joint_lump__tesseravue_chassis_link_visual_1'>
          <pose>0.3715 0.050001 0.129999 1.5708 -0 1.5708</pose>
          <geometry>
            <mesh>
              <scale>0.0015 0.0015 0.0015</scale>
              <uri>model://yaskawa_mh5_description/meshes/mh5/collision/BIN_PICKING_MODULE_1CH_ASM.stl</uri>
            </mesh>
          </geometry>
        </visual>
        <visual name='link_r_fixed_joint_lump__tesseravue_camera_link_visual_2'>
          <pose>0.4515 0.146001 0.149999 1e-06 4e-06 5e-06</pose>
          <geometry>
            <cylinder>
              <length>0.001</length>
              <radius>0.0005</radius>
            </cylinder>
          </geometry>
        </visual>
        <sensor name='TesseraVue' type='camera'>
          <visualize>1</visualize>
          <update_rate>12</update_rate>
          <camera name='TesseraVue'>
            <horizontal_fov>1.089</horizontal_fov>
            <image>
              <width>3840</width>
              <height>2160</height>
              <format>R8G8B8</format>
            </image>
            <clip>
              <near>0.05</near>
              <far>8</far>
            </clip>
          </camera>
          <plugin name='camera_controller' filename='libgazebo_ros_camera.so'>
            <frameName>3dcamera_optical</frameName>
            <min_depth>0.1</min_depth>
            <max_depth>100.0</max_depth>
          </plugin>
          <pose>0.4515 0.146001 0.149999 1e-06 4e-06 5e-06</pose>
        </sensor>
        <self_collide>0</self_collide>
        <enable_wind>0</enable_wind>
        <kinematic>0</kinematic>
      </link>
      <joint name='joint_b' type='revolute'>
        <pose relative_to='link_r'>0.467 0 0 0 -0 0</pose>
        <parent>link_r</parent>
        <child>link_b</child>
        <axis>
          <xyz>0 -1 0</xyz>
          <limit>
            <lower>-2.1817</lower>
            <upper>2.1817</upper>
            <effort>100</effort>
            <velocity>3.48</velocity>
          </limit>
          <dynamics>
            <spring_reference>0</spring_reference>
            <spring_stiffness>0</spring_stiffness>
          </dynamics>
        </axis>
      </joint>
      <link name='link_b'>
        <pose relative_to='joint_b'>0 0 0 0 -0 0</pose>
        <inertial>
          <pose>0 0 0 0 -0 0</pose>
          <mass>1</mass>
          <inertia>
            <ixx>1</ixx>
            <ixy>0</ixy>
            <ixz>0</ixz>
            <iyy>1</iyy>
            <iyz>0</iyz>
            <izz>1</izz>
          </inertia>
        </inertial>
        <collision name='link_b_collision'>
          <pose>0 0 0 0 -0 0</pose>
          <geometry>
            <mesh>
              <scale>2 2 2</scale>
              <uri>model://yaskawa_mh5_description/meshes/mh5/collision/MH5_B_AXIS.stl</uri>
            </mesh>
          </geometry>
          <max_contacts>10</max_contacts>
          <surface>
            <contact>
              <ode/>
            </contact>
            <bounce/>
            <friction>
              <torsional>
                <ode/>
              </torsional>
              <ode/>
            </friction>
          </surface>
        </collision>
        <visual name='link_b_visual'>
          <pose>0 0 0 0 -0 0</pose>
          <geometry>
            <mesh>
              <scale>2 2 2</scale>
              <uri>model://yaskawa_mh5_description/meshes/mh5/visual/MH5_B_AXIS.stl</uri>
            </mesh>
          </geometry>
        </visual>
        <self_collide>0</self_collide>
        <enable_wind>0</enable_wind>
        <kinematic>0</kinematic>
      </link>
      <joint name='joint_t' type='revolute'>
        <pose relative_to='link_b'>0.173 0 0 0 -0 0</pose>
        <parent>link_b</parent>
        <child>link_t</child>
        <axis>
          <xyz>0 -1 0</xyz>
          <limit>
            <lower>-6.2831</lower>
            <upper>6.2831</upper>
            <effort>100</effort>
            <velocity>6.97</velocity>
          </limit>
          <dynamics>
            <spring_reference>0</spring_reference>
            <spring_stiffness>0</spring_stiffness>
          </dynamics>
        </axis>
      </joint>
      <link name='link_t'>
        <pose relative_to='joint_t'>0 0 0 0 -0 0</pose>
        <inertial>
          <pose>0 0 0 0 -0 0</pose>
          <mass>1</mass>
          <inertia>
            <ixx>1</ixx>
            <ixy>0</ixy>
            <ixz>0</ixz>
            <iyy>1</iyy>
            <iyz>0</iyz>
            <izz>1</izz>
          </inertia>
        </inertial>
        <collision name='link_t_collision'>
          <pose>0 0 0 0 -0 0</pose>
          <geometry>
            <mesh>
              <scale>2 2 2</scale>
              <uri>model://yaskawa_mh5_description/meshes/mh5/collision/MH5_T_AXIS.stl</uri>
            </mesh>
          </geometry>
          <max_contacts>10</max_contacts>
          <surface>
            <contact>
              <ode/>
            </contact>
            <bounce/>
            <friction>
              <torsional>
                <ode/>
              </torsional>
              <ode/>
            </friction>
          </surface>
        </collision>
        <visual name='link_t_visual'>
          <pose>0 0 0 0 -0 0</pose>
          <geometry>
            <mesh>
              <scale>2 2 2</scale>
              <uri>model://yaskawa_mh5_description/meshes/mh5/visual/MH5_T_AXIS.stl</uri>
            </mesh>
          </geometry>
        </visual>
        <self_collide>0</self_collide>
        <enable_wind>0</enable_wind>
        <kinematic>0</kinematic>
      </link>
      <static>0</static>
      <plugin name='gazebo_ros2_control' filename='libgazebo_ros2_control.so'>
        <robot_param>robot_description</robot_param>
        <robot_param_node>robot_state_publisher</robot_param_node>
        <parameters>/home/ubuntu/ros2-dev/simulator/install/yaskawa_mh5_controller/share/yaskawa_mh5_controller/config/mh5_ros2_controller.yaml</parameters>
      </plugin>
      <pose>0 0 0 0 -0 0</pose>
    </model>
    <model name='bowl'>
      <link name='link'>
        <inertial>
          <pose>0 0 0.0175 0 -0 0</pose>
          <mass>0.1</mass>
          <inertia>
            <ixx>0.000250308</ixx>
            <ixy>0</ixy>
            <ixz>0</ixz>
            <iyy>0.000250308</iyy>
            <iyz>0</iyz>
            <izz>0.0004802</izz>
          </inertia>
        </inertial>
        <collision name='collision'>
          <pose>0 0 0.0175 0 -0 0</pose>
          <geometry>
            <cylinder>
              <radius>0.098</radius>
              <length>0.035</length>
            </cylinder>
          </geometry>
          <max_contacts>10</max_contacts>
          <surface>
            <contact>
              <ode/>
            </contact>
            <bounce/>
            <friction>
              <torsional>
                <ode/>
              </torsional>
              <ode/>
            </friction>
          </surface>
        </collision>
        <visual name='visual'>
          <geometry>
            <mesh>
              <uri>model://bowl/meshes/bowl.dae</uri>
            </mesh>
          </geometry>
        </visual>
        <self_collide>0</self_collide>
        <enable_wind>0</enable_wind>
        <kinematic>0</kinematic>
      </link>
      <pose>1.15072 0.352392 0 0 -0 0</pose>
    </model>
    <model name='beer'>
      <link name='link'>
        <pose>0 0 0.115 0 -0 0</pose>
        <inertial>
          <mass>0.39</mass>
          <inertia>
            <ixx>0.00058</ixx>
            <ixy>0</ixy>
            <ixz>0</ixz>
            <iyy>0.00058</iyy>
            <iyz>0</iyz>
            <izz>0.00019</izz>
          </inertia>
          <pose>0 0 0 0 -0 0</pose>
        </inertial>
        <collision name='collision'>
          <geometry>
            <cylinder>
              <radius>0.055</radius>
              <length>0.23</length>
            </cylinder>
          </geometry>
          <max_contacts>10</max_contacts>
          <surface>
            <contact>
              <ode/>
            </contact>
            <bounce/>
            <friction>
              <torsional>
                <ode/>
              </torsional>
              <ode/>
            </friction>
          </surface>
        </collision>
        <visual name='visual'>
          <geometry>
            <cylinder>
              <radius>0.055</radius>
              <length>0.23</length>
            </cylinder>
          </geometry>
          <material>
            <script>
              <uri>model://beer/materials/scripts</uri>
              <uri>model://beer/materials/textures</uri>
              <name>Beer/Diffuse</name>
            </script>
          </material>
        </visual>
        <self_collide>0</self_collide>
        <enable_wind>0</enable_wind>
        <kinematic>0</kinematic>
      </link>
      <pose>1.22306 0.028985 0 0 -0 0</pose>
    </model>
    <model name='coke_can'>
      <link name='link'>
        <inertial>
          <pose>0 0 0.06 0 -0 0</pose>
          <mass>0.39</mass>
          <inertia>
            <ixx>0.00055575</ixx>
            <ixy>0</ixy>
            <ixz>0</ixz>
            <iyy>0.00055575</iyy>
            <iyz>0</iyz>
            <izz>0.0001755</izz>
          </inertia>
        </inertial>
        <collision name='collision'>
          <pose>0.003937 0.004724 -0.18 0 -0 0</pose>
          <geometry>
            <mesh>
              <uri>model://coke_can/meshes/coke_can.dae</uri>
            </mesh>
          </geometry>
          <surface>
            <friction>
              <ode>
                <mu>1</mu>
                <mu2>1</mu2>
              </ode>
              <torsional>
                <ode/>
              </torsional>
            </friction>
            <contact>
              <ode>
                <kp>1e+07</kp>
                <kd>1</kd>
                <min_depth>0.001</min_depth>
                <max_vel>0.1</max_vel>
              </ode>
            </contact>
            <bounce/>
          </surface>
          <max_contacts>10</max_contacts>
        </collision>
        <visual name='visual'>
          <pose>0.003937 0.004724 -0.18 0 -0 0</pose>
          <geometry>
            <mesh>
              <uri>model://coke_can/meshes/coke_can.dae</uri>
            </mesh>
          </geometry>
        </visual>
        <self_collide>0</self_collide>
        <enable_wind>0</enable_wind>
        <kinematic>0</kinematic>
      </link>
      <pose>1.58274 -0.079264 0 0 -0 0</pose>
    </model>
    <model name='disk_part'>
      <link name='link'>
        <inertial>
          <pose>0 0 0.02895 0 -0 0</pose>
          <mass>0.5</mass>
          <inertia>
            <ixx>0.00321218</ixx>
            <ixy>0</ixy>
            <ixz>0</ixz>
            <iyy>0.00321218</iyy>
            <iyz>0</iyz>
            <izz>0.00614499</izz>
          </inertia>
        </inertial>
        <collision name='collision'>
          <pose>0 0 0.02895 0 -0 0</pose>
          <geometry>
            <cylinder>
              <length>0.0579</length>
              <radius>0.15678</radius>
            </cylinder>
          </geometry>
          <max_contacts>10</max_contacts>
          <surface>
            <contact>
              <ode/>
            </contact>
            <bounce/>
            <friction>
              <torsional>
                <ode/>
              </torsional>
              <ode/>
            </friction>
          </surface>
        </collision>
        <visual name='visual'>
          <geometry>
            <mesh>
              <uri>model://disk_part/meshes/disk.dae</uri>
            </mesh>
          </geometry>
          <material>
            <script>
              <uri>model://arm_part/materials/scripts</uri>
              <uri>model://arm_part/materials/textures</uri>
              <name>ArmPart/Diffuse</name>
            </script>
          </material>
        </visual>
        <self_collide>0</self_collide>
        <enable_wind>0</enable_wind>
        <kinematic>0</kinematic>
      </link>
      <pose>1.13688 -0.318232 0 0 -0 0</pose>
    </model>
    <model name='coke_can_0'>
      <link name='link'>
        <inertial>
          <pose>0 0 0.06 0 -0 0</pose>
          <mass>0.39</mass>
          <inertia>
            <ixx>0.00055575</ixx>
            <ixy>0</ixy>
            <ixz>0</ixz>
            <iyy>0.00055575</iyy>
            <iyz>0</iyz>
            <izz>0.0001755</izz>
          </inertia>
        </inertial>
        <collision name='collision'>
          <pose>0.003937 0.004724 -0.18 0 -0 0</pose>
          <geometry>
            <mesh>
              <uri>model://coke_can/meshes/coke_can.dae</uri>
            </mesh>
          </geometry>
          <surface>
            <friction>
              <ode>
                <mu>1</mu>
                <mu2>1</mu2>
              </ode>
              <torsional>
                <ode/>
              </torsional>
            </friction>
            <contact>
              <ode>
                <kp>1e+07</kp>
                <kd>1</kd>
                <min_depth>0.001</min_depth>
                <max_vel>0.1</max_vel>
              </ode>
            </contact>
            <bounce/>
          </surface>
          <max_contacts>10</max_contacts>
        </collision>
        <visual name='visual'>
          <pose>0.003937 0.004724 -0.18 0 -0 0</pose>
          <geometry>
            <mesh>
              <uri>model://coke_can/meshes/coke_can.dae</uri>
            </mesh>
          </geometry>
        </visual>
        <self_collide>0</self_collide>
        <enable_wind>0</enable_wind>
        <kinematic>0</kinematic>
      </link>
      <pose>1.51873 -0.398987 0 0 -0 0</pose>
    </model>
    <state world_name='default'>
      <sim_time>423 522000000</sim_time>
      <real_time>425 526716061</real_time>
      <wall_time>1721937368 498754306</wall_time>
      <iterations>423522</iterations>
      <model name='beer'>
        <pose>1.22306 0.028985 -7e-06 -1e-06 -0 -4e-06</pose>
        <scale>1 1 1</scale>
        <link name='link'>
          <pose>1.22306 0.028985 0.114993 -1e-06 -0 -4e-06</pose>
          <velocity>0 0 0 0 -0 0</velocity>
          <acceleration>0 0 -9.8 0 -0 0</acceleration>
          <wrench>0 0 -3.822 0 -0 0</wrench>
        </link>
      </model>
      <model name='bowl'>
        <pose>1.15072 0.352392 -5e-06 4.7e-05 4.7e-05 1e-06</pose>
        <scale>1 1 1</scale>
        <link name='link'>
          <pose>1.15072 0.352392 -5e-06 4.7e-05 4.7e-05 1e-06</pose>
          <velocity>0 -0 -0.000973 0.08317 0.08317 -0</velocity>
          <acceleration>2.72184 -2.72184 -0.884028 1.56431 -1.56436 -3.14159</acceleration>
          <wrench>0.272184 -0.272184 -0.088403 0 -0 0</wrench>
        </link>
      </model>
      <model name='coke_can'>
        <pose>1.58273 -0.079411 -0.002718 -0.058601 0.005325 -0.00052</pose>
        <scale>1 1 1</scale>
        <link name='link'>
          <pose>1.58273 -0.079411 -0.002718 -0.058601 0.005325 -0.00052</pose>
          <velocity>0 0 0 0 -0 0</velocity>
          <acceleration>0.040181 0.040012 0.000597 -0.695641 0.704832 0.068526</acceleration>
          <wrench>0.015671 0.015605 0.000233 0 -0 0</wrench>
        </link>
      </model>
      <model name='coke_can_0'>
        <pose>1.51871 -0.399125 -0.002659 -0.055112 0.007741 -0.000483</pose>
        <scale>1 1 1</scale>
        <link name='link'>
          <pose>1.51871 -0.399125 -0.002659 -0.055112 0.007741 -0.000483</pose>
          <velocity>0 0 0 0 -0 0</velocity>
          <acceleration>0.040402 0.022034 0.002042 -0.382614 0.708503 0.07172</acceleration>
          <wrench>0.015757 0.008593 0.000796 0 -0 0</wrench>
        </link>
      </model>
      <model name='disk_part'>
        <pose>1.13688 -0.318232 -5e-06 -3.2e-05 -3.2e-05 0</pose>
        <scale>1 1 1</scale>
        <link name='link'>
          <pose>1.13688 -0.318232 -5e-06 -3.2e-05 -3.2e-05 0</pose>
          <velocity>0 0 0 0 -0 0</velocity>
          <acceleration>-3.16087 3.16086 0.31441 0.78697 -0.786932 -3.14159</acceleration>
          <wrench>-1.58043 1.58043 0.157205 0 -0 0</wrench>
        </link>
      </model>
      <model name='ground_plane'>
        <pose>0 0 0 0 -0 0</pose>
        <scale>1 1 1</scale>
        <link name='link'>
          <pose>0 0 0 0 -0 0</pose>
          <velocity>0 0 0 0 -0 0</velocity>
          <acceleration>0 0 0 0 -0 0</acceleration>
          <wrench>0 0 0 0 -0 0</wrench>
        </link>
      </model>
      <model name='yaskawa_mh5lf'>
        <pose>-0 0 4.7e-05 9e-06 -5e-06 0</pose>
        <scale>1 1 1</scale>
        <link name='base_link'>
          <pose>-0 0 4.7e-05 9e-06 -5e-06 0</pose>
          <velocity>-0 -1e-06 0.009475 0.001743 -0.00093 1e-06</velocity>
          <acceleration>-3.2e-05 -0.001274 18.9505 0.344749 -1.28149 -3.13978</acceleration>
          <wrench>-3.2e-05 -0.001274 18.9505 0 -0 0</wrench>
        </link>
        <link name='link_b'>
          <pose>0.630407 -0.095933 0.666223 7.1e-05 0.870074 -0.151001</pose>
          <velocity>-0.002022 -0.001056 0.004866 0.00011 0.003038 0.001749</velocity>
          <acceleration>-2.64146 -2.21724 14.7606 -1.28873 1.03406 -1.39181</acceleration>
          <wrench>-2.64146 -2.21724 14.7606 0 -0 0</wrench>
        </link>
        <link name='link_l'>
          <pose>0.173995 -0.02648 0.461046 9e-06 0.011812 -0.15101</pose>
          <velocity>-0.000415 -0.000795 0.009358 0.002235 0.003352 -0.000529</velocity>
          <acceleration>-0.843369 -1.59885 18.9492 0.837035 0.719593 2.61316</acceleration>
          <wrench>-0.843369 -1.59885 18.9492 0 -0 0</wrench>
        </link>
        <link name='link_r'>
          <pose>0.332695 -0.050634 1.02316 7.1e-05 0.869989 -0.151001</pose>
          <velocity>0.001164 -0.001969 0.007687 0.001048 0.009169 0.001755</velocity>
          <acceleration>-0.356387 -3.34179 16.3592 -0.42067 1.21559 -1.46591</acceleration>
          <wrench>-0.712774 -6.68357 32.7184 0 -0 0</wrench>
        </link>
        <link name='link_s'>
          <pose>-1e-06 -2e-06 0.199047 9e-06 -3e-06 -0.15101</pose>
          <velocity>-0.000178 -0.000316 0.009364 0.001666 -0.000897 -0.000536</velocity>
          <acceleration>-0.362653 -0.663328 18.8397 0.267998 -1.3143 2.6062</acceleration>
          <wrench>-0.362653 -0.663328 18.8397 0 -0 0</wrench>
        </link>
        <link name='link_t'>
          <pose>0.740683 -0.112713 0.533986 7.1e-05 0.869994 -0.151001</pose>
          <velocity>-0.002385 -0.000831 0.004474 -0.000257 0.000704 0.001738</velocity>
          <acceleration>-2.88149 -1.7617 14.4418 1.48611 -0.226292 1.73849</acceleration>
          <wrench>-2.88149 -1.7617 14.4418 0 -0 0</wrench>
        </link>
        <link name='link_u'>
          <pose>0.181234 -0.027587 1.081 1.3e-05 0.869989 -0.151</pose>
          <velocity>0.001677 -0.002113 0.00922 0.002997 0.00887 -0.000537</velocity>
          <acceleration>0.671417 -3.99736 18.8161 1.59902 1.48492 2.60597</acceleration>
          <wrench>0.671417 -3.99736 18.8161 0 -0 0</wrench>
        </link>
      </model>
      <light name='sun'>
        <pose>0 0 10 0 -0 0</pose>
      </light>
    </state>
    <gui fullscreen='0'>
      <camera name='user_camera'>
        <pose>-3.39158 -3.91656 7.27117 -0 1.03564 0.704194</pose>
        <view_controller>orbit</view_controller>
        <projection_type>perspective</projection_type>
      </camera>
    </gui>
  </world>
</sdf>
